<?xml version='1.0' ?>
<sdf version='1.10'>
  <world name='mecanum_drive'>
    <physics name='1ms' type='ignored'>
      <max_step_size>0.001</max_step_size>
      <real_time_factor>1</real_time_factor>
      <real_time_update_rate>1000</real_time_update_rate>
    </physics>
    <plugin name='gz::sim::systems::Physics' filename='gz-sim-physics-system'/>
    <plugin name='gz::sim::systems::UserCommands' filename='gz-sim-user-commands-system'/>
    <plugin name='gz::sim::systems::SceneBroadcaster' filename='gz-sim-scene-broadcaster-system'/>
    <gravity>0 0 -9.8</gravity>
    <magnetic_field>5.5644999999999998e-06 2.2875799999999999e-05 -4.2388400000000002e-05</magnetic_field>
    <atmosphere type='adiabatic'/>
    <scene>
      <ambient>0.4 0.4 0.4 1</ambient>
      <background>0.7 0.7 0.7 1</background>
      <shadows>true</shadows>
    </scene>

    <model name="track_model">
      <static>true</static>
      <link name="track_link">
        <visual name="wall">
          <geometry>
            <mesh>
              <uri>meshes/model.dae</uri>
              <submesh>
                <name>wall</name>
              </submesh>
            </mesh>
          </geometry>
          <material>
            <diffuse>1.0 1.0 1.0 1.0</diffuse>
            <specular>0.0 0.0 0.0 1.0</specular>
            <pbr>
              <metal>
                <albedo_map>meshes/walls.jpg</albedo_map>
              </metal>
            </pbr>
          </material>
        </visual>
        <visual name="field">
          <geometry>
            <mesh>
              <uri>meshes/model.dae</uri>
              <submesh>
                <name>field</name>
              </submesh>
            </mesh>
          </geometry>
          <material>
            <diffuse>1.0 1.0 1.0 1.0</diffuse>
            <specular>0.0 0.0 0.0 1.0</specular>
            <pbr>
              <metal>
                <albedo_map>meshes/field.png</albedo_map>
              </metal>
            </pbr>
          </material>
        </visual>
        <visual name="outer_walls">
          <geometry>
            <mesh>
              <uri>meshes/model.dae</uri>
              <submesh>
                <name>outer_walls</name>
              </submesh>
            </mesh>
          </geometry>
          <material>
            <diffuse>1.0 1.0 1.0 1.0</diffuse>
            <specular>0.0 0.0 0.0 1.0</specular>
            <pbr>
              <metal/>
            </pbr>
          </material>
        </visual>
        <visual name="inner_walls">
          <geometry>
            <mesh>
              <uri>meshes/model.dae</uri>
              <submesh>
                <name>inner_walls</name>
              </submesh>
            </mesh>
          </geometry>
          <material>
            <diffuse>1.0 1.0 1.0 1.0</diffuse>
            <specular>0.0 0.0 0.0 1.0</specular>
            <pbr>
              <metal/>
            </pbr>
          </material>
        </visual>
        <visual name="road">
          <geometry>
            <mesh>
              <uri>meshes/model.dae</uri>
              <submesh>
                <name>road</name>
              </submesh>
            </mesh>
          </geometry>
          <material>
            <diffuse>1.0 1.0 1.0 1.0</diffuse>
            <specular>0.0 0.0 0.0 1.0</specular>
            <pbr>
              <metal>
                <albedo_map>meshes/road.png</albedo_map>
              </metal>
            </pbr>
          </material>
        </visual>
        <visual name="il">
          <geometry>
            <mesh>
              <uri>meshes/model.dae</uri>
              <submesh>
                <name>il</name>
              </submesh>
            </mesh>
          </geometry>
          <material>
            <diffuse>1.0 1.0 1.0 1.0</diffuse>
            <specular>0.0 0.0 0.0 1.0</specular>
            <pbr>
              <metal>
                <albedo_map>meshes/outerLine.png</albedo_map>
              </metal>
            </pbr>
          </material>
        </visual>
        <visual name="ol">
          <geometry>
            <mesh>
              <uri>meshes/model.dae</uri>
              <submesh>
                <name>ol</name>
              </submesh>
            </mesh>
          </geometry>
          <material>
            <diffuse>1.0 1.0 1.0 1.0</diffuse>
            <specular>0.0 0.0 0.0 1.0</specular>
            <pbr>
              <metal>
                <albedo_map>meshes/outerLine.png</albedo_map>
              </metal>
            </pbr>
          </material>
        </visual>
        <visual name="cl">
          <geometry>
            <mesh>
              <uri>meshes/model.dae</uri>
              <submesh>
                <name>cl</name>
              </submesh>
            </mesh>
          </geometry>
          <material>
            <diffuse>1.0 1.0 1.0 1.0</diffuse>
            <specular>0.0 0.0 0.0 1.0</specular>
            <pbr>
              <metal>
                <albedo_map>meshes/centerLine.png</albedo_map>
              </metal>
            </pbr>
          </material>
        </visual>
        <visual name="start_line">
          <geometry>
            <mesh>
              <uri>meshes/model.dae</uri>
              <submesh>
                <name>start_line</name>
              </submesh>
            </mesh>
          </geometry>
          <material>
            <diffuse>1.0 1.0 1.0 1.0</diffuse>
            <specular>0.0 0.0 0.0 1.0</specular>
            <pbr>
              <metal>
                <albedo_map>meshes/startline.png</albedo_map>
              </metal>
            </pbr>
          </material>
        </visual>
        <light name="Lamp" type="point">
          <diffuse>1.0 1.0 1.0 1.0</diffuse>
          <attenuation>
            <range>30.002</range>
            <linear>0.0</linear>
            <quadratic>1.0</quadratic>
            <constant>0.0</constant>
          </attenuation>
          <cast_shadows>true</cast_shadows>
          <intensity>1.0</intensity>
        </light>
        <collision name="collision">
          <geometry>
            <mesh>
              <uri>meshes/model.dae</uri>
            </mesh>
          </geometry>
          <surface>
            <contact>
              <collide_bitmask>0x01</collide_bitmask>
            </contact>
          </surface>
        </collision>
      </link>
      <pose>0 0 0 0 0 0</pose>
    </model>
    
    <model name='ground_plane'>
      <static>true</static>
      <link name='link'>
        <collision name='collision'>
          <geometry>
            <plane>
              <normal>0 0 1</normal>
              <size>100 100</size>
            </plane>
          </geometry>
          <surface>
            <friction>
              <ode>
                <mu>50</mu>
              </ode>
            </friction>
            <bounce/>
            <contact/>
          </surface>
        </collision>
        <visual name='visual'>
          <geometry>
            <plane>
              <normal>0 0 1</normal>
              <size>100 100</size>
            </plane>
          </geometry>
          <material>
            <ambient>0.8 0.8 0.8 1</ambient>
            <diffuse>0.8 0.8 0.8 1</diffuse>
            <specular>0.8 0.8 0.8 1</specular>
          </material>
        </visual>
        <pose>0 0 0 0 0 0</pose>
        <inertial>
          <pose>0 0 0 0 0 0</pose>
          <mass>1</mass>
          <inertia>
            <ixx>1</ixx>
            <ixy>0</ixy>
            <ixz>0</ixz>
            <iyy>1</iyy>
            <iyz>0</iyz>
            <izz>1</izz>
          </inertia>
        </inertial>
        <enable_wind>false</enable_wind>
      </link>
      <pose>0 0 0 0 0 0</pose>
      <self_collide>false</self_collide>
    </model>

    <model name='vehicle_blue' xmlns:gz='http://gazebosim.org/schema'>
      <!-- <pose>0 2 0.325 0 0 0</pose> -->
      <pose>-6.65 14.61 0.33 0 0 -1.55</pose>
      <link name='chassis'>
        <pose>-0.151427 0 0.175 0 0 0</pose>
        <inertial>
          <mass>1.14395</mass>
          <inertia>
            <ixx>0.126164</ixx>
            <ixy>0</ixy>
            <ixz>0</ixz>
            <iyy>0.416519</iyy>
            <iyz>0</iyz>
            <izz>0.481014</izz>
          </inertia>
          <pose>0 0 0 0 0 0</pose>
        </inertial>
        <visual name='visual'>
          <geometry>
            <box>
              <size>2.01142 1 0.568726</size>
            </box>
          </geometry>
          <material>
            <ambient>0.5 0.5 1 1</ambient>
            <diffuse>0.5 0.5 1 1</diffuse>
            <specular>0 0 1 1</specular>
          </material>
        </visual>
        <collision name='collision'>
          <geometry>
            <box>
              <size>2.01142 1 0.568726</size>
            </box>
          </geometry>
          <surface>
            <friction>
              <ode/>
            </friction>
            <bounce/>
            <contact/>
          </surface>
        </collision>
        <enable_wind>false</enable_wind>
      </link>
      <link name='front_left_wheel'>
        <pose>0.554283 0.625029 -0.025 -1.5707 0 0</pose>
        <inertial>
          <mass>2</mass>
          <inertia>
            <ixx>0.145833</ixx>
            <ixy>0</ixy>
            <ixz>0</ixz>
            <iyy>0.145833</iyy>
            <iyz>0</iyz>
            <izz>0.125</izz>
          </inertia>
          <pose>0 0 0 0 0 0</pose>
        </inertial>
        <visual name='visual'>
          <pose>0 0 0 1.5707 0 0</pose>
          <geometry>
            <mesh>
              <uri>https://fuel.gazebosim.org/1.0/OpenRobotics/models/Mecanum lift/tip/files/meshes/mecanum_wheel_left.STL</uri>
              <scale>0.006 0.006 0.006</scale>
            </mesh>
          </geometry>
          <material>
            <ambient>0.2 0.2 0.2 1</ambient>
            <diffuse>0.2 0.2 0.2 1</diffuse>
            <specular>0.2 0.2 0.2 1</specular>
          </material>
        </visual>
        <collision name='collision'>
          <geometry>
            <sphere>
              <radius>0.3</radius>
            </sphere>
          </geometry>
          <surface>
            <friction>
              <ode>
                <mu>1</mu>
                <mu2>0</mu2>
                <fdir1 gz:expressed_in='chassis'>1 -1 0</fdir1>
              </ode>
            </friction>
            <bounce/>
            <contact/>
          </surface>
        </collision>
        <enable_wind>false</enable_wind>
      </link>
      <link name='rear_left_wheel'>
        <pose>-0.957138 0.625029 -0.025 -1.5707 0 0</pose>
        <inertial>
          <mass>2</mass>
          <inertia>
            <ixx>0.145833</ixx>
            <ixy>0</ixy>
            <ixz>0</ixz>
            <iyy>0.145833</iyy>
            <iyz>0</iyz>
            <izz>0.125</izz>
          </inertia>
          <pose>0 0 0 0 0 0</pose>
        </inertial>
        <visual name='visual'>
          <pose>0 0 0 1.5707 0 0</pose>
          <geometry>
            <mesh>
              <uri>https://fuel.gazebosim.org/1.0/OpenRobotics/models/Mecanum lift/tip/files/meshes/mecanum_wheel_right.STL</uri>
              <scale>0.006 0.006 0.006</scale>
            </mesh>
          </geometry>
          <material>
            <ambient>0.2 0.2 0.2 1</ambient>
            <diffuse>0.2 0.2 0.2 1</diffuse>
            <specular>0.2 0.2 0.2 1</specular>
          </material>
        </visual>
        <collision name='collision'>
          <geometry>
            <sphere>
              <radius>0.3</radius>
            </sphere>
          </geometry>
          <surface>
            <friction>
              <ode>
                <mu>1</mu>
                <mu2>0</mu2>
                <fdir1 gz:expressed_in='chassis'>1 1 0</fdir1>
              </ode>
            </friction>
            <bounce/>
            <contact/>
          </surface>
        </collision>
        <enable_wind>false</enable_wind>
      </link>
      <link name='front_right_wheel'>
        <pose>0.554282 -0.625029 -0.025 -1.5707 0 0</pose>
        <inertial>
          <mass>2</mass>
          <inertia>
            <ixx>0.145833</ixx>
            <ixy>0</ixy>
            <ixz>0</ixz>
            <iyy>0.145833</iyy>
            <iyz>0</iyz>
            <izz>0.125</izz>
          </inertia>
          <pose>0 0 0 0 0 0</pose>
        </inertial>
        <visual name='visual'>
          <pose>0 0 0 1.5707 0 0</pose>
          <geometry>
            <mesh>
              <uri>https://fuel.gazebosim.org/1.0/OpenRobotics/models/Mecanum lift/tip/files/meshes/mecanum_wheel_right.STL</uri>
              <scale>0.006 0.006 0.006</scale>
            </mesh>
          </geometry>
          <material>
            <ambient>0.2 0.2 0.2 1</ambient>
            <diffuse>0.2 0.2 0.2 1</diffuse>
            <specular>0.2 0.2 0.2 1</specular>
          </material>
        </visual>
        <collision name='collision'>
          <geometry>
            <sphere>
              <radius>0.3</radius>
            </sphere>
          </geometry>
          <surface>
            <friction>
              <ode>
                <mu>1</mu>
                <mu2>0</mu2>
                <fdir1 gz:expressed_in='chassis'>1 1 0</fdir1>
              </ode>
            </friction>
            <bounce/>
            <contact/>
          </surface>
        </collision>
        <enable_wind>false</enable_wind>
      </link>
      <link name='rear_right_wheel'>
        <pose>-0.957138 -0.625029 -0.025 -1.5707 0 0</pose>
        <inertial>
          <mass>2</mass>
          <inertia>
            <ixx>0.145833</ixx>
            <ixy>0</ixy>
            <ixz>0</ixz>
            <iyy>0.145833</iyy>
            <iyz>0</iyz>
            <izz>0.125</izz>
          </inertia>
          <pose>0 0 0 0 0 0</pose>
        </inertial>
        <visual name='visual'>
          <pose>0 0 0 1.5707 0 0</pose>
          <geometry>
            <mesh>
              <uri>https://fuel.gazebosim.org/1.0/OpenRobotics/models/Mecanum lift/tip/files/meshes/mecanum_wheel_left.STL</uri>
              <scale>0.006 0.006 0.006</scale>
            </mesh>
          </geometry>
          <material>
            <ambient>0.2 0.2 0.2 1</ambient>
            <diffuse>0.2 0.2 0.2 1</diffuse>
            <specular>0.2 0.2 0.2 1</specular>
          </material>
        </visual>
        <collision name='collision'>
          <geometry>
            <sphere>
              <radius>0.3</radius>
            </sphere>
          </geometry>
          <surface>
            <friction>
              <ode>
                <mu>1</mu>
                <mu2>0</mu2>
                <fdir1 gz:expressed_in='chassis'>1 -1 0</fdir1>
              </ode>
            </friction>
            <bounce/>
            <contact/>
          </surface>
        </collision>
        <enable_wind>false</enable_wind>
      </link>
      
      <joint name='front_left_wheel_joint' type='revolute'>
        <parent>chassis</parent>
        <child>front_left_wheel</child>
        <axis>
          <xyz>0 0 1</xyz>
          <limit>
            <lower>-1.79769e+308</lower>
            <upper>1.79769e+308</upper>
            <effort>inf</effort>
            <velocity>inf</velocity>
            <stiffness>100000000</stiffness>
            <dissipation>1</dissipation>
          </limit>
          <dynamics>
            <spring_reference>0</spring_reference>
            <spring_stiffness>0</spring_stiffness>
            <damping>0</damping>
            <friction>0</friction>
          </dynamics>
        </axis>
        <pose>0 0 0 0 0 0</pose>
      </joint>
      <joint name='front_right_wheel_joint' type='revolute'>
        <parent>chassis</parent>
        <child>front_right_wheel</child>
        <axis>
          <xyz>0 0 1</xyz>
          <limit>
            <lower>-1.79769e+308</lower>
            <upper>1.79769e+308</upper>
            <effort>inf</effort>
            <velocity>inf</velocity>
            <stiffness>100000000</stiffness>
            <dissipation>1</dissipation>
          </limit>
          <dynamics>
            <spring_reference>0</spring_reference>
            <spring_stiffness>0</spring_stiffness>
            <damping>0</damping>
            <friction>0</friction>
          </dynamics>
        </axis>
        <pose>0 0 0 0 0 0</pose>
      </joint>
      <joint name='rear_left_wheel_joint' type='revolute'>
        <parent>chassis</parent>
        <child>rear_left_wheel</child>
        <axis>
          <xyz>0 0 1</xyz>
          <limit>
            <lower>-1.79769e+308</lower>
            <upper>1.79769e+308</upper>
            <effort>inf</effort>
            <velocity>inf</velocity>
            <stiffness>100000000</stiffness>
            <dissipation>1</dissipation>
          </limit>
          <dynamics>
            <spring_reference>0</spring_reference>
            <spring_stiffness>0</spring_stiffness>
            <damping>0</damping>
            <friction>0</friction>
          </dynamics>
        </axis>
        <pose>0 0 0 0 0 0</pose>
      </joint>
      <joint name='rear_right_wheel_joint' type='revolute'>
        <parent>chassis</parent>
        <child>rear_right_wheel</child>
        <axis>
          <xyz>0 0 1</xyz>
          <limit>
            <lower>-1.79769e+308</lower>
            <upper>1.79769e+308</upper>
            <effort>inf</effort>
            <velocity>inf</velocity>
            <stiffness>100000000</stiffness>
            <dissipation>1</dissipation>
          </limit>
          <dynamics>
            <spring_reference>0</spring_reference>
            <spring_stiffness>0</spring_stiffness>
            <damping>0</damping>
            <friction>0</friction>
          </dynamics>
        </axis>
        <pose>0 0 0 0 0 0</pose>
      </joint>
      
      <plugin name='gz::sim::systems::MecanumDrive' filename='gz-sim-mecanum-drive-system'>
        <front_left_joint>front_left_wheel_joint</front_left_joint>
        <front_right_joint>front_right_wheel_joint</front_right_joint>
        <back_left_joint>rear_left_wheel_joint</back_left_joint>
        <back_right_joint>rear_right_wheel_joint</back_right_joint>
        <wheel_separation>1.25</wheel_separation>
        <wheelbase>1.511</wheelbase>
        <wheel_radius>0.3</wheel_radius>
        <min_acceleration>-5</min_acceleration>
        <max_acceleration>5</max_acceleration>
        <topic>/cmd_vel</topic>
      </plugin>
      <static>false</static>
      <self_collide>false</self_collide>

      <!-- <link name="front_camera_link">
        <pose>1.1 0 0.6 0 0 0</pose>
        <inertial>
          <mass>0.1</mass>
          <inertia>
            <ixx>0.001</ixx>
            <iyy>0.001</iyy>
            <izz>0.001</izz>
          </inertia>
        </inertial>
        <visual name="camera_visual">
          <geometry>
            <box>
              <size>0.05 0.05 0.05</size>
            </box>
          </geometry>
          <material>
            <ambient>0 0 0 1</ambient>
            <diffuse>0 0 0 1</diffuse>
          </material>
        </visual>
        <sensor name="front_camera" type="camera">
          <pose>0 0 0 0 0 0</pose>
          <always_on>true</always_on>
          <update_rate>30</update_rate>
          <visualize>true</visualize>
          <camera>
            <horizontal_fov>1.047</horizontal_fov>
            <image>
              <width>640</width>
              <height>480</height>
              <format>R8G8B8</format>
            </image>
            <clip>
              <near>0.1</near>
              <far>100</far>
            </clip>
          </camera>
          <plugin name='gz::sim::systems::Sensors' filename='gz-sim-sensors-system'>
            <render_engine>ogre2</render_engine>
          </plugin>
        </sensor>
      </link>

      <joint name="front_camera_joint" type="fixed">
        <parent>chassis</parent>
        <child>front_camera_link</child>
        <pose>0 0 0 0 0 0</pose>
      </joint> -->





<!-- ______SENSORS______ --> 

<!-- Camera -->
<link name="camera_link">
  <pose>1.1 0 0.6 0 0.087222222 0</pose> <!-- pitch + 5 [deg] = 0.0872 [rad]--> 

  <inertial>
    <mass>0.1</mass>
    <inertia>
      <ixx>0.001</ixx>
      <iyy>0.001</iyy>
      <izz>0.001</izz>
    </inertia>
  </inertial>

  <visual name="camera_visual">
    <geometry>
      <box>
        <size>0.05 0.05 0.05</size>
      </box>
    </geometry>
    <material>
      <ambient>0 0 0 1</ambient>
      <diffuse>0 0 0 1</diffuse>
    </material>
  </visual>

  <sensor name="camera_sensor" type="camera">
    <pose>0 0 0 0 0 0</pose>
    <always_on>true</always_on>
    <update_rate>30</update_rate> 
    <visualize>true</visualize>
    <camera>
      <horizontal_fov>1.203666667</horizontal_fov> <!-- horizontal FOV: 69 +/- 1 deg ->  1,203666667 rad--> 
      <image>
        <!-- Orginal resolution: 1920x1080 -> Rescale to 480x270 --> 
        <width>480</width>
        <height>270</height>
        <format>R8G8B8</format>
      </image>
      <clip>
        <near>0.1</near>
        <far>100</far>
      </clip>
    </camera>
  </sensor>
</link>

<!-- Connection camera with car -->
<joint name="camera_joint" type="fixed">
  <parent>chassis</parent>
  <child>camera_link</child>
  <pose>0 0 0 0 0 0</pose>
</joint>

<!-- ______ Lidar ______ --> 
<link name="lidar_link">
  <pose>1.1 0 0.4 0 0 0</pose> <!-- --> 

  <inertial>
    <mass>0.1</mass>
    <inertia>
      <ixx>0.001</ixx>
      <iyy>0.001</iyy>
      <izz>0.001</izz>
    </inertia>
  </inertial>

  <visual name="lidar_visual">
    <geometry>
      <box>
        <size>0.05 0.05 0.05</size>
      </box>
    </geometry>
    <material>
      <ambient>0 0 0 1</ambient>
      <diffuse>0 0 0 1</diffuse>
    </material>
  </visual>

<sensor type="ray" name="lidar">
  <ray>
    <scan>
      <horizontal> <!-- Ang resolution 0.45 deg = 0,00785 rad--> 
        <samples>280</samples> <!-- samples = (max_angle - min_angle)/ang_resolution --> 
        <resolution>1</resolution> <!-- 1 for 2D Lidar --> 
        <min_angle>-1.099</min_angle> <!-- -63 deg -> -1.099 rad --> 
        <max_angle>1.099</max_angle> <!-- 63 deg -> 1.099 rad --> 
      </horizontal>
    </scan>
    <range> <!-- 0.2 - 12 [m] -->
      <min>0.2</min>
      <max>12.0</max>
      <resolution>0.01</resolution>
    </range>
  </ray>
</sensor>

</link>

<!-- Connection lidar with car -->
<joint name="lidar_joint" type="fixed">
  <parent>chassis</parent>
  <child>lidar_link</child>
  <pose>0 0 0 0 0 0</pose>
</joint>

<!-- Plugin for sensors -->
<plugin name='gz::sim::systems::Sensors' filename='gz-sim-sensors-system'>
  <render_engine>ogre2</render_engine>
  <start_enabled>true</start_enabled>
</plugin>




      
    </model>

    <light name='sun' type='directional'>
      <pose>0 0 10 0 0 0</pose>
      <cast_shadows>true</cast_shadows>
      <intensity>1</intensity>
      <direction>-0.5 0.1 -0.9</direction>
      <diffuse>1 1 1 1</diffuse>
      <specular>0.5 0.5 0.5 1</specular>
      <attenuation>
        <range>1000</range>
        <linear>0.01</linear>
        <constant>0.9</constant>
        <quadratic>0.001</quadratic>
      </attenuation>
      <spot>
        <inner_angle>0</inner_angle>
        <outer_angle>0</outer_angle>
        <falloff>0</falloff>
      </spot>
    </light>
  </world>
</sdf>
